Workbook

Sheet 調査業務リスト
A1: No. | B1: 大項目 | C1: 中項目 | D1: 小項目 | E1: 調査ブロック | F1: 大細目(番号) | G1: 大細目(内容) | H1: 細目(記号) | I1: 細目内容 | J1: 調査手法 | K1: 重要度(1-5) | L1: AI活用前 想定工数(人日) | M1: AI削減率(%) | N1: AI活用ツール・手法 | O1: AI活用後 工数(人日) | P1: 開始予定 | Q1: 完了予定 | R1: 人件費単価 (円/人日) | S1: 人件費(円) | T1: その他コスト(円) | U1: コスト内訳 | V1: 実際にかかる費用(円) | W1: 備考・前提 | X1: Research / analysis | Y1: Report Progress | Z1: Done
A2: 1 | B2: 1. 木材の長期間利用による炭素貯蔵効果の評価手法の検討 | C2: (1) フランスのダイナミックLCAを含む海外での制度事例や検討内容の収集・分析 | D2: ① フランスRE2020におけるダイナミックLCA関連情報の収集・分析 | E2: (1) 政策及び制度調査 | F2: ① | G2: 建築環境性能評価制度（建築物LCA）の全体構造 | H2: ア | I2: RE2020における建築物LCAの位置付け | J2: 文献・政策資料調査 | K2: 5 | L2: 3 | M2: 60 | N2: Claude/ChatGPTでフランス語文献の翻訳・要約・論点抽出を一次処理、DeepLで補助翻訳、人間が検証 | O2: =ROUND(L2*(1-M2/100)*2,0)/2 -> 1 | P2: 2026年5月上旬 | Q2: 2026年6月初旬 | R2: 40000 | S2: =O2*R2 -> 40000 | T2: 0 | V2: =S2+T2 -> 40000 | W2: ★優先群: 制度化背景・基礎ガイダンス | X2: 1 | Z2: FALSE
A3: 2 | B3: 1. 木材の長期間利用による炭素貯蔵効果の評価手法の検討 | C3: (1) フランスのダイナミックLCAを含む海外での制度事例や検討内容の収集・分析 | D3: ① フランスRE2020におけるダイナミックLCA関連情報の収集・分析 | E3: (1) 政策及び制度調査 | F3: ① | G3: 建築環境性能評価制度（建築物LCA）の全体構造 | H3: イ | I3: 環境性能評価方法（非住宅・住宅、新築・既築住宅等） | J3: 文献・政策資料調査 | K3: 5 | L3: 4 | M3: 60 | N3: Claude/ChatGPTでフランス語文献の翻訳・要約・論点抽出を一次処理、DeepLで補助翻訳、人間が検証 | O3: =ROUND(L3*(1-M3/100)*2,0)/2 -> 1.5 | P3: 2026年5月上旬 | Q3: 2026年6月初旬 | R3: 40000 | S3: =O3*R3 -> 60000 | T3: 0 | V3: =S3+T3 -> 60000 | W3: ★優先群: 制度化背景・基礎ガイダンス | X3: 1 | Z3: FALSE
A4: 3 | B4: 1. 木材の長期間利用による炭素貯蔵効果の評価手法の検討 | C4: (1) フランスのダイナミックLCAを含む海外での制度事例や検討内容の収集・分析 | D4: ① フランスRE2020におけるダイナミックLCA関連情報の収集・分析 | E4: (1) 政策及び制度調査 | F4: ① | G4: 建築環境性能評価制度（建築物LCA）の全体構造 | H4: ウ | I4: Level(s)及びEN15978（建築物の環境性能評価方法）との関係性 | J4: 文献・政策資料調査 | K4: 4 | L4: 3 | M4: 60 | N4: Claude/ChatGPTでフランス語文献の翻訳・要約・論点抽出を一次処理、DeepLで補助翻訳、人間が検証 | O4: =ROUND(L4*(1-M4/100)*2,0)/2 -> 1 | P4: 2026年5月上旬 | Q4: 2026年6月初旬 | R4: 40000 | S4: =O4*R4 -> 40000 | T4: 0 | V4: =S4+T4 -> 40000 | W4: ★優先群: 制度化背景・基礎ガイダンス | X4: 1 | Z4: FALSE
A5: 4 | B5: 1. 木材の長期間利用による炭素貯蔵効果の評価手法の検討 | C5: (1) フランスのダイナミックLCAを含む海外での制度事例や検討内容の収集・分析 | D5: ① フランスRE2020におけるダイナミックLCA関連情報の収集・分析 | E5: (1) 政策及び制度調査 | F5: ④ | G5: 制度導入の背景および検討プロセスの整理 | H5: ア | I5: 初期検討から導入に至った経緯 | J5: 文献・政策資料調査 | K5: 3 | L5: 2 | M5: 60 | N5: Claude/ChatGPTでフランス語文献の翻訳・要約・論点抽出を一次処理、DeepLで補助翻訳、人間が検証 | O5: =ROUND(L5*(1-M5/100)*2,0)/2 -> 1 | P5: 2026年5月上旬 | Q5: 2026年6月初旬 | R5: 40000 | S5: =O5*R5 -> 40000 | T5: 0 | V5: =S5+T5 -> 40000 | W5: ★優先群: 制度化背景 | X5: 1 | Z5: FALSE
A6: 5 | B6: 1. 木材の長期間利用による炭素貯蔵効果の評価手法の検討 | C6: (1) フランスのダイナミックLCAを含む海外での制度事例や検討内容の収集・分析 | D6: ① フランスRE2020におけるダイナミックLCA関連情報の収集・分析 | E6: (1) 政策及び制度調査 | F6: ④ | G6: 制度導入の背景および検討プロセスの整理 | H6: イ | I6: 所管省庁及び外郭組織、関連する国家戦略 | J6: 文献・政策資料調査 | K6: 3 | L6: 2 | M6: 60 | N6: Claude/ChatGPTでフランス語文献の翻訳・要約・論点抽出を一次処理、DeepLで補助翻訳、人間が検証 | O6: =ROUND(L6*(1-M6/100)*2,0)/2 -> 1 | P6: 2026年5月上旬 | Q6: 2026年6月初旬 | R6: 40000 | S6: =O6*R6 -> 40000 | T6: 0 | V6: =S6+T6 -> 40000 | W6: ★優先群: 制度化背景 | X6: 1 | Z6: FALSE
A7: 6 | B7: 1. 木材の長期間利用による炭素貯蔵効果の評価手法の検討 | C7: (1) フランスのダイナミックLCAを含む海外での制度事例や検討内容の収集・分析 | D7: ① フランスRE2020におけるダイナミックLCA関連情報の収集・分析 | E7: (1) 政策及び制度調査 | F7: ④ | G7: 制度導入の背景および検討プロセスの整理 | H7: ウ | I7: 目的と狙い、課題認識 | J7: 文献・政策資料調査 | K7: 3 | L7: 2 | M7: 60 | N7: Claude/ChatGPTでフランス語文献の翻訳・要約・論点抽出を一次処理、DeepLで補助翻訳、人間が検証 | O7: =ROUND(L7*(1-M7/100)*2,0)/2 -> 1 | P7: 2026年5月上旬 | Q7: 2026年6月初旬 | R7: 40000 | S7: =O7*R7 -> 40000 | T7: 0 | V7: =S7+T7 -> 40000 | W7: ★優先群: 制度化背景 | X7: 1 | Z7: FALSE
A8: 7 | B8: 1. 木材の長期間利用による炭素貯蔵効果の評価手法の検討 | C8: (1) フランスのダイナミックLCAを含む海外での制度事例や検討内容の収集・分析 | D8: ① フランスRE2020におけるダイナミックLCA関連情報の収集・分析 | E8: (1) 政策及び制度調査 | F8: ④ | G8: 制度導入の背景および検討プロセスの整理 | H8: エ | I8: フランスの林業木材利用戦略との関係性 | J8: 文献・政策資料調査 | K8: 4 | L8: 3 | M8: 60 | N8: Claude/ChatGPTでフランス語文献の翻訳・要約・論点抽出を一次処理、DeepLで補助翻訳、人間が検証 | O8: =ROUND(L8*(1-M8/100)*2,0)/2 -> 1 | P8: 2026年5月上旬 | Q8: 2026年6月初旬 | R8: 40000 | S8: =O8*R8 -> 40000 | T8: 0 | V8: =S8+T8 -> 40000 | W8: ★優先群: 制度化背景 | X8: 1 | Z8: FALSE
A9: 8 | B9: 1. 木材の長期間利用による炭素貯蔵効果の評価手法の検討 | C9: (1) フランスのダイナミックLCAを含む海外での制度事例や検討内容の収集・分析 | D9: ① フランスRE2020におけるダイナミックLCA関連情報の収集・分析 | E9: (1) 政策及び制度調査 | F9: ① | G9: 建築環境性能評価制度（建築物LCA）の全体構造 | H9: エ | I9: サーキュラーエコノミー施策との関係性 | J9: 文献・政策資料調査 | K9: 3 | L9: 2 | M9: 60 | N9: Claude/ChatGPTでフランス語文献の翻訳・要約・論点抽出を一次処理、DeepLで補助翻訳、人間が検証 | O9: =ROUND(L9*(1-M9/100)*2,0)/2 -> 1 | P9: 2026年6月中旬 | Q9: 2026年7月下旬 | R9: 40000 | S9: =O9*R9 -> 40000 | T9: 0 | V9: =S9+T9 -> 40000 | X9: 1 | Z9: FALSE
A10: 9 | B10: 1. 木材の長期間利用による炭素貯蔵効果の評価手法の検討 | C10: (1) フランスのダイナミックLCAを含む海外での制度事例や検討内容の収集・分析 | D10: ① フランスRE2020におけるダイナミックLCA関連情報の収集・分析 | E10: (1) 政策及び制度調査 | F10: ② | G10: ダイナミックLCAの要件整理 | H10: ア | I10: 対象建築物の種別と範囲、並びに導入時の段階適用内容 | J10: 文献・政策資料調査 | K10: 5 | L10: 3 | M10: 65 | N10: AIで文献翻訳・要件抽出を自動化、人間が検証 | O10: =ROUND(L10*(1-M10/100)*2,0)/2 -> 1 | P10: 2026年6月中旬 | Q10: 2026年7月下旬 | R10: 40000 | S10: =O10*R10 -> 40000 | T10: 0 | V10: =S10+T10 -> 40000 | Z10: FALSE
A11: 10 | B11: 1. 木材の長期間利用による炭素貯蔵効果の評価手法の検討 | C11: (1) フランスのダイナミックLCAを含む海外での制度事例や検討内容の収集・分析 | D11: ① フランスRE2020におけるダイナミックLCA関連情報の収集・分析 | E11: (1) 政策及び制度調査 | F11: ② | G11: ダイナミックLCAの要件整理 | H11: イ | I11: 遅延排出の評価根拠 | J11: 文献・政策資料調査 | K11: 5 | L11: 4 | M11: 50 | N11: AIで根拠資料の翻訳・要約、人間が解釈精査 | O11: =ROUND(L11*(1-M11/100)*2,0)/2 -> 2 | P11: 2026年6月中旬 | Q11: 2026年7月下旬 | R11: 40000 | S11: =O11*R11 -> 80000 | T11: 0 | V11: =S11+T11 -> 80000 | W11: 解釈判断が重要 | Z11: FALSE
A12: 11 | B12: 1. 木材の長期間利用による炭素貯蔵効果の評価手法の検討 | C12: (1) フランスのダイナミックLCAを含む海外での制度事例や検討内容の収集・分析 | D12: ① フランスRE2020におけるダイナミックLCA関連情報の収集・分析 | E12: (1) 政策及び制度調査 | F12: ② | G12: ダイナミックLCAの要件整理 | H12: ウ | I12: 各種パラメータ内容 | J12: 文献・政策資料調査 | K12: 4 | L12: 3 | M12: 65 | N12: AIでパラメータ表の自動整理・翻訳 | O12: =ROUND(L12*(1-M12/100)*2,0)/2 -> 1 | P12: 2026年6月中旬 | Q12: 2026年7月下旬 | R12: 40000 | S12: =O12*R12 -> 40000 | T12: 0 | V12: =S12+T12 -> 40000 | Z12: FALSE
A13: 12 | B13: 1. 木材の長期間利用による炭素貯蔵効果の評価手法の検討 | C13: (1) フランスのダイナミックLCAを含む海外での制度事例や検討内容の収集・分析 | D13: ① フランスRE2020におけるダイナミックLCA関連情報の収集・分析 | E13: (1) 政策及び制度調査 | F13: ③ | G13: 生物由来炭素及び炭素貯蔵評価の制度的位置付け | H13: ア | I13: 貯蔵量算定方法 | J13: 文献・政策資料調査 | K13: 5 | L13: 4 | M13: 50 | N13: AIで算定式・計算例の翻訳整理、人間が精査 | O13: =ROUND(L13*(1-M13/100)*2,0)/2 -> 2 | P13: 2026年6月中旬 | Q13: 2026年7月下旬 | R13: 40000 | S13: =O13*R13 -> 80000 | T13: 0 | V13: =S13+T13 -> 80000 | W13: 計算根拠の精査が必要 | Z13: FALSE
A14: 13 | B14: 1. 木材の長期間利用による炭素貯蔵効果の評価手法の検討 | C14: (1) フランスのダイナミックLCAを含む海外での制度事例や検討内容の収集・分析 | D14: ① フランスRE2020におけるダイナミックLCA関連情報の収集・分析 | E14: (1) 政策及び制度調査 | F14: ③ | G14: 生物由来炭素及び炭素貯蔵評価の制度的位置付け | H14: イ | I14: 評価期間の設定根拠 | J14: 文献・政策資料調査 | K14: 5 | L14: 3 | M14: 65 | N14: AIで根拠資料の翻訳・要点抽出 | O14: =ROUND(L14*(1-M14/100)*2,0)/2 -> 1 | P14: 2026年6月中旬 | Q14: 2026年7月下旬 | R14: 40000 | S14: =O14*R14 -> 40000 | T14: 0 | V14: =S14+T14 -> 40000 | Z14: FALSE
A15: 14 | B15: 1. 木材の長期間利用による炭素貯蔵効果の評価手法の検討 | C15: (1) フランスのダイナミックLCAを含む海外での制度事例や検討内容の収集・分析 | D15: ① フランスRE2020におけるダイナミックLCA関連情報の収集・分析 | E15: (1) 政策及び制度調査 | F15: ③ | G15: 生物由来炭素及び炭素貯蔵評価の制度的位置付け | H15: ウ | I15: 解体及び再利用での排出扱い | J15: 文献・政策資料調査 | K15: 4 | L15: 3 | M15: 65 | N15: AIで規定の翻訳・整理を自動化 | O15: =ROUND(L15*(1-M15/100)*2,0)/2 -> 1 | P15: 2026年6月中旬 | Q15: 2026年7月下旬 | R15: 40000 | S15: =O15*R15 -> 40000 | T15: 0 | V15: =S15+T15 -> 40000 | Z15: FALSE
A16: 15 | B16: 1. 木材の長期間利用による炭素貯蔵効果の評価手法の検討 | C16: (1) フランスのダイナミックLCAを含む海外での制度事例や検討内容の収集・分析 | D16: ① フランスRE2020におけるダイナミックLCA関連情報の収集・分析 | E16: (2) 技術及び手法の調査 | F16: ① | G16: ダイナミックLCAの理論的枠組み | H16: ア | I16: 動的LCA（時間軸評価）導入の基本概念 | J16: 文献・政策資料調査 | K16: 5 | L16: 3 | M16: 40 | N16: AIで概念整理・比較表の初稿生成、人間が専門的精査・修正 | O16: =ROUND(L16*(1-M16/100)*2,0)/2 -> 2 | P16: 2026年6月中旬 | Q16: 2026年8月上旬 | R16: 40000 | S16: =O16*R16 -> 80000 | T16: 0 | V16: =S16+T16 -> 80000 | W16: 理論部分は人間の理解が必須 | Z16: FALSE
A17: 16 | B17: 1. 木材の長期間利用による炭素貯蔵効果の評価手法の検討 | C17: (1) フランスのダイナミックLCAを含む海外での制度事例や検討内容の収集・分析 | D17: ① フランスRE2020におけるダイナミックLCA関連情報の収集・分析 | E17: (2) 技術及び手法の調査 | F17: ① | G17: ダイナミックLCAの理論的枠組み | H17: イ | I17: 評価期間の根拠 | J17: 文献・政策資料調査 | K17: 5 | L17: 3 | M17: 40 | N17: AIで概念整理・比較表の初稿生成、人間が専門的精査・修正 | O17: =ROUND(L17*(1-M17/100)*2,0)/2 -> 2 | P17: 2026年6月中旬 | Q17: 2026年8月上旬 | R17: 40000 | S17: =O17*R17 -> 80000 | T17: 0 | V17: =S17+T17 -> 80000 | Z17: FALSE
A18: 17 | B18: 1. 木材の長期間利用による炭素貯蔵効果の評価手法の検討 | C18: (1) フランスのダイナミックLCAを含む海外での制度事例や検討内容の収集・分析 | D18: ① フランスRE2020におけるダイナミックLCA関連情報の収集・分析 | E18: (2) 技術及び手法の調査 | F18: ① | G18: ダイナミックLCAの理論的枠組み | H18: ウ | I18: 従来型静的LCA（GWP100）との差異 | J18: 文献・政策資料調査 | K18: 5 | L18: 4 | M18: 50 | N18: AIで概念整理・比較表の初稿生成、人間が専門的精査・修正 | O18: =ROUND(L18*(1-M18/100)*2,0)/2 -> 2 | P18: 2026年6月中旬 | Q18: 2026年8月上旬 | R18: 40000 | S18: =O18*R18 -> 80000 | T18: 0 | V18: =S18+T18 -> 80000 | W18: 比較表をAIで初稿生成 | Z18: FALSE
A19: 18 | B19: 1. 木材の長期間利用による炭素貯蔵効果の評価手法の検討 | C19: (1) フランスのダイナミックLCAを含む海外での制度事例や検討内容の収集・分析 | D19: ① フランスRE2020におけるダイナミックLCA関連情報の収集・分析 | E19: (2) 技術及び手法の調査 | F19: ② | G19: 評価指標及び算定方法 | H19: ア | I19: 時間軸評価の処理方法、パラメータ根拠 | J19: 文献・政策資料調査 | K19: 5 | L19: 4 | M19: 30 | N19: AIで概念整理・比較表の初稿生成、人間が専門的精査・修正 | O19: =ROUND(L19*(1-M19/100)*2,0)/2 -> 3 | P19: 2026年6月中旬 | Q19: 2026年8月上旬 | R19: 40000 | S19: =O19*R19 -> 120000 | T19: 0 | V19: =S19+T19 -> 120000 | W19: 数式・パラメータの精査が必要 | Z19: FALSE
A20: 19 | B20: 1. 木材の長期間利用による炭素貯蔵効果の評価手法の検討 | C20: (1) フランスのダイナミックLCAを含む海外での制度事例や検討内容の収集・分析 | D20: ① フランスRE2020におけるダイナミックLCA関連情報の収集・分析 | E20: (2) 技術及び手法の調査 | F20: ② | G20: 評価指標及び算定方法 | H20: イ | I20: 炭素循環（吸収・固定・放出）の扱い | J20: 文献・政策資料調査 | K20: 5 | L20: 4 | M20: 40 | N20: AIで概念整理・比較表の初稿生成、人間が専門的精査・修正 | O20: =ROUND(L20*(1-M20/100)*2,0)/2 -> 2.5 | P20: 2026年7月下旬 | Q20: 2026年9月上旬 | R20: 40000 | S20: =O20*R20 -> 100000 | T20: 0 | V20: =S20+T20 -> 100000 | Z20: FALSE
A21: 20 | B21: 1. 木材の長期間利用による炭素貯蔵効果の評価手法の検討 | C21: (1) フランスのダイナミックLCAを含む海外での制度事例や検討内容の収集・分析 | D21: ① フランスRE2020におけるダイナミックLCA関連情報の収集・分析 | E21: (2) 技術及び手法の調査 | F21: ② | G21: 評価指標及び算定方法 | H21: ウ | I21: 放射強制力の考え方との関係性 | J21: 文献・政策資料調査 | K21: 4 | L21: 3 | M21: 40 | N21: AIで概念整理・比較表の初稿生成、人間が専門的精査・修正 | O21: =ROUND(L21*(1-M21/100)*2,0)/2 -> 2 | P21: 2026年7月下旬 | Q21: 2026年9月上旬 | R21: 40000 | S21: =O21*R21 -> 80000 | T21: 0 | V21: =S21+T21 -> 80000 | Z21: FALSE
A22: 21 | B22: 1. 木材の長期間利用による炭素貯蔵効果の評価手法の検討 | C22: (1) フランスのダイナミックLCAを含む海外での制度事例や検討内容の収集・分析 | D22: ① フランスRE2020におけるダイナミックLCA関連情報の収集・分析 | E22: (2) 技術及び手法の調査 | F22: ③ | G22: 建築物LCA算定における位置付け | H22: ア | I22: 算定環境（マニュアル、ツール、人材育成）の状況 | J22: 文献・政策資料調査 | K22: 4 | L22: 3 | M22: 50 | N22: AIで概念整理・比較表の初稿生成、人間が専門的精査・修正 | O22: =ROUND(L22*(1-M22/100)*2,0)/2 -> 1.5 | P22: 2026年7月下旬 | Q22: 2026年9月上旬 | R22: 40000 | S22: =O22*R22 -> 60000 | T22: 0 | V22: =S22+T22 -> 60000 | Z22: FALSE
A23: 22 | B23: 1. 木材の長期間利用による炭素貯蔵効果の評価手法の検討 | C23: (1) フランスのダイナミックLCAを含む海外での制度事例や検討内容の収集・分析 | D23: ① フランスRE2020におけるダイナミックLCA関連情報の収集・分析 | E23: (2) 技術及び手法の調査 | F23: ③ | G23: 建築物LCA算定における位置付け | H23: イ | I23: 静的LCA評価との関係性 | J23: 文献・政策資料調査 | K23: 4 | L23: 3 | M23: 50 | N23: AIで概念整理・比較表の初稿生成、人間が専門的精査・修正 | O23: =ROUND(L23*(1-M23/100)*2,0)/2 -> 1.5 | P23: 2026年7月下旬 | Q23: 2026年9月上旬 | R23: 40000 | S23: =O23*R23 -> 60000 | T23: 0 | V23: =S23+T23 -> 60000 | Z23: FALSE
A24: 23 | B24: 1. 木材の長期間利用による炭素貯蔵効果の評価手法の検討 | C24: (1) フランスのダイナミックLCAを含む海外での制度事例や検討内容の収集・分析 | D24: ① フランスRE2020におけるダイナミックLCA関連情報の収集・分析 | E24: (2) 技術及び手法の調査 | F24: ③ | G24: 建築物LCA算定における位置付け | H24: ウ | I24: 評価結果の利用方法、表示方法 | J24: 文献・政策資料調査 | K24: 4 | L24: 3 | M24: 60 | N24: Claude/ChatGPTでフランス語文献の翻訳・要約・論点抽出を一次処理、DeepLで補助翻訳、人間が検証 | O24: =ROUND(L24*(1-M24/100)*2,0)/2 -> 1 | P24: 2026年7月下旬 | Q24: 2026年9月上旬 | R24: 40000 | S24: =O24*R24 -> 40000 | T24: 0 | V24: =S24+T24 -> 40000 | Z24: FALSE
A25: 24 | B25: 1. 木材の長期間利用による炭素貯蔵効果の評価手法の検討 | C25: (1) フランスのダイナミックLCAを含む海外での制度事例や検討内容の収集・分析 | D25: ① フランスRE2020におけるダイナミックLCA関連情報の収集・分析 | E25: (3) 制度を支える情報基盤の構造把握 | F25: ① | G25: 建材のCO₂等排出量原単位データベースの構造分析 | H25: ア | I25: INIESにおけるデータ格納状況 | J25: 文献・政策資料調査 | K25: 5 | L25: 4 | M25: 70 | N25: AIでDBスキーマ・データ構造を自動分析、表形式整理 | O25: =ROUND(L25*(1-M25/100)*2,0)/2 -> 1 | P25: 2026年7月上旬 | Q25: 2026年8月下旬 | R25: 40000 | S25: =O25*R25 -> 40000 | T25: 0 | V25: =S25+T25 -> 40000 | W25: DBスキーマ分析はAIが特に得意 | Z25: FALSE
A26: 25 | B26: 1. 木材の長期間利用による炭素貯蔵効果の評価手法の検討 | C26: (1) フランスのダイナミックLCAを含む海外での制度事例や検討内容の収集・分析 | D26: ① フランスRE2020におけるダイナミックLCA関連情報の収集・分析 | E26: (3) 制度を支える情報基盤の構造把握 | F26: ① | G26: 建材のCO₂等排出量原単位データベースの構造分析 | H26: イ | I26: 動的評価に必要なパラメータの設定状況 | J26: 文献・政策資料調査 | K26: 5 | L26: 4 | M26: 65 | N26: AIでパラメータ仕様の翻訳・整理を自動化 | O26: =ROUND(L26*(1-M26/100)*2,0)/2 -> 1.5 | P26: 2026年7月上旬 | Q26: 2026年8月下旬 | R26: 40000 | S26: =O26*R26 -> 60000 | T26: 0 | V26: =S26+T26 -> 60000 | Z26: FALSE
A27: 26 | B27: 1. 木材の長期間利用による炭素貯蔵効果の評価手法の検討 | C27: (1) フランスのダイナミックLCAを含む海外での制度事例や検討内容の収集・分析 | D27: ① フランスRE2020におけるダイナミックLCA関連情報の収集・分析 | E27: (3) 制度を支える情報基盤の構造把握 | F27: ① | G27: 建材のCO₂等排出量原単位データベースの構造分析 | H27: ウ | I27: 静的LCAデータとの構造差異 | J27: 文献・政策資料調査 | K27: 4 | L27: 3 | M27: 65 | N27: AIで両者の比較表を自動生成、人間が検証 | O27: =ROUND(L27*(1-M27/100)*2,0)/2 -> 1 | P27: 2026年7月上旬 | Q27: 2026年8月下旬 | R27: 40000 | S27: =O27*R27 -> 40000 | T27: 0 | V27: =S27+T27 -> 40000 | Z27: FALSE
A28: 27 | B28: 1. 木材の長期間利用による炭素貯蔵効果の評価手法の検討 | C28: (1) フランスのダイナミックLCAを含む海外での制度事例や検討内容の収集・分析 | D28: ① フランスRE2020におけるダイナミックLCA関連情報の収集・分析 | E28: (3) 制度を支える情報基盤の構造把握 | F28: ① | G28: 建材のCO₂等排出量原単位データベースの構造分析 | H28: エ | I28: データ更新及び品質管理体制 | J28: 文献・政策資料調査 | K28: 3 | L28: 2 | M28: 60 | N28: Claude/ChatGPTでフランス語文献の翻訳・要約・論点抽出を一次処理、DeepLで補助翻訳、人間が検証 | O28: =ROUND(L28*(1-M28/100)*2,0)/2 -> 1 | P28: 2026年7月上旬 | Q28: 2026年8月下旬 | R28: 40000 | S28: =O28*R28 -> 40000 | T28: 0 | V28: =S28+T28 -> 40000 | Z28: FALSE
A29: 28 | B29: 1. 木材の長期間利用による炭素貯蔵効果の評価手法の検討 | C29: (1) フランスのダイナミックLCAを含む海外での制度事例や検討内容の収集・分析 | D29: ① フランスRE2020におけるダイナミックLCA関連情報の収集・分析 | E29: (3) 制度を支える情報基盤の構造把握 | F29: ② | G29: 炭素フローモデルの仕様把握 | H29: ア | I29: 木材製品等の炭素貯蔵機能の評価方法 | J29: 文献・政策資料調査 | K29: 5 | L29: 4 | M29: 40 | N29: AIで概念整理・比較表の初稿生成、人間が専門的精査・修正 | O29: =ROUND(L29*(1-M29/100)*2,0)/2 -> 2.5 | P29: 2026年8月中旬 | Q29: 2026年9月下旬 | R29: 40000 | S29: =O29*R29 -> 100000 | T29: 0 | V29: =S29+T29 -> 100000 | W29: 専門的解釈が必要 | Z29: FALSE
A30: 29 | B30: 1. 木材の長期間利用による炭素貯蔵効果の評価手法の検討 | C30: (1) フランスのダイナミックLCAを含む海外での制度事例や検討内容の収集・分析 | D30: ① フランスRE2020におけるダイナミックLCA関連情報の収集・分析 | E30: (3) 制度を支える情報基盤の構造把握 | F30: ② | G30: 炭素フローモデルの仕様把握 | H30: イ | I30: エンドオブライフシナリオのモデル化方法 | J30: 文献・政策資料調査 | K30: 5 | L30: 4 | M30: 50 | N30: AIでシナリオ定義の翻訳・整理、人間が解釈 | O30: =ROUND(L30*(1-M30/100)*2,0)/2 -> 2 | P30: 2026年8月中旬 | Q30: 2026年9月下旬 | R30: 40000 | S30: =O30*R30 -> 80000 | T30: 0 | V30: =S30+T30 -> 80000 | Z30: FALSE
A31: 30 | B31: 1. 木材の長期間利用による炭素貯蔵効果の評価手法の検討 | C31: (1) フランスのダイナミックLCAを含む海外での制度事例や検討内容の収集・分析 | D31: ① フランスRE2020におけるダイナミックLCA関連情報の収集・分析 | E31: (3) 制度を支える情報基盤の構造把握 | F31: ② | G31: 炭素フローモデルの仕様把握 | H31: ウ | I31: 評価期間の設定根拠 | J31: 文献・政策資料調査 | K31: 4 | L31: 3 | M31: 60 | N31: AIで根拠資料を翻訳・整理 | O31: =ROUND(L31*(1-M31/100)*2,0)/2 -> 1 | P31: 2026年8月中旬 | Q31: 2026年9月下旬 | R31: 40000 | S31: =O31*R31 -> 40000 | T31: 0 | V31: =S31+T31 -> 40000 | Z31: FALSE
A32: 31 | B32: 1. 木材の長期間利用による炭素貯蔵効果の評価手法の検討 | C32: (1) フランスのダイナミックLCAを含む海外での制度事例や検討内容の収集・分析 | D32: ① フランスRE2020におけるダイナミックLCA関連情報の収集・分析 | E32: (3) 制度を支える情報基盤の構造把握 | F32: ③ | G32: 建築物LCA算定プロセスとの接続構造 | H32: ア | I32: A-Dモジュールとの関係 | J32: 文献・政策資料調査 | K32: 4 | L32: 3 | M32: 55 | N32: AIで概念整理・比較表の初稿生成、人間が専門的精査・修正 | O32: =ROUND(L32*(1-M32/100)*2,0)/2 -> 1.5 | P32: 2026年8月中旬 | Q32: 2026年9月下旬 | R32: 40000 | S32: =O32*R32 -> 60000 | T32: 0 | V32: =S32+T32 -> 60000 | Z32: FALSE
A33: 32 | B33: 1. 木材の長期間利用による炭素貯蔵効果の評価手法の検討 | C33: (1) フランスのダイナミックLCAを含む海外での制度事例や検討内容の収集・分析 | D33: ① フランスRE2020におけるダイナミックLCA関連情報の収集・分析 | E33: (3) 制度を支える情報基盤の構造把握 | F33: ③ | G33: 建築物LCA算定プロセスとの接続構造 | H33: イ | I33: LCCO₂計算フローでの動的評価の位置づけ | J33: 文献・政策資料調査 | K33: 4 | L33: 3 | M33: 50 | N33: AIで概念整理・比較表の初稿生成、人間が専門的精査・修正 | O33: =ROUND(L33*(1-M33/100)*2,0)/2 -> 1.5 | P33: 2026年8月中旬 | Q33: 2026年9月下旬 | R33: 40000 | S33: =O33*R33 -> 60000 | T33: 0 | V33: =S33+T33 -> 60000 | Z33: FALSE
A34: 33 | B34: 1. 木材の長期間利用による炭素貯蔵効果の評価手法の検討 | C34: (1) フランスのダイナミックLCAを含む海外での制度事例や検討内容の収集・分析 | D34: ① フランスRE2020におけるダイナミックLCA関連情報の収集・分析 | E34: (3) 制度を支える情報基盤の構造把握 | F34: ③ | G34: 建築物LCA算定プロセスとの接続構造 | H34: ウ | I34: 算定結果表示方式 | J34: 文献・政策資料調査 | K34: 3 | L34: 2 | M34: 65 | N34: Claude/ChatGPTでフランス語文献の翻訳・要約・論点抽出を一次処理、DeepLで補助翻訳、人間が検証 | O34: =ROUND(L34*(1-M34/100)*2,0)/2 -> 0.5 | P34: 2026年8月中旬 | Q34: 2026年9月下旬 | R34: 40000 | S34: =O34*R34 -> 20000 | T34: 0 | V34: =S34+T34 -> 20000 | Z34: FALSE
A35: 34 | B35: 1. 木材の長期間利用による炭素貯蔵効果の評価手法の検討 | C35: (1) フランスのダイナミックLCAを含む海外での制度事例や検討内容の収集・分析 | D35: ① フランスRE2020におけるダイナミックLCA関連情報の収集・分析 | E35: (4) 関係機関及び専門家調査 | F35: ① | G35: 建築及びLCA関係者へのヒアリング | H35: ア | I35: ダイナミックLCA導入のメリット・デメリット【メイン:Web面談】 | J35: 電子メール・Web面談ヒアリング | K35: 5 | L35: 4 | M35: 30 | N35: AIは質問票作成・議事録整理・要約のみ。実施は人間 | O35: =ROUND(L35*(1-M35/100)*2,0)/2 -> 3 | P35: 2026年8月中旬 | Q35: 2026年10月中旬 | R35: 50000 | S35: =O35*R35 -> 150000 | T35: 30000 | U35: 通訳費20,000円+謝礼10,000円 | V35: =S35+T35 -> 180000 | W35: ★メイン機関(LCA関係者)1機関に集約。Web面談で実施 / Web面談1セッション約60-90分 | Z35: FALSE
A36: 35 | B36: 1. 木材の長期間利用による炭素貯蔵効果の評価手法の検討 | C36: (1) フランスのダイナミックLCAを含む海外での制度事例や検討内容の収集・分析 | D36: ① フランスRE2020におけるダイナミックLCA関連情報の収集・分析 | E36: (4) 関係機関及び専門家調査 | F36: ① | G36: 建築及びLCA関係者へのヒアリング | H36: イ | I36: 建築物LCAの環境整備及び浸透状況【サブ:メール調査】 | J36: 電子メール・Web面談ヒアリング | K36: 4 | L36: 1 | M36: 50 | N36: AIで質問票作成・回答要約、人間が検証 | O36: =ROUND(L36*(1-M36/100)*2,0)/2 -> 0.5 | P36: 2026年8月中旬 | Q36: 2026年10月中旬 | R36: 50000 | S36: =O36*R36 -> 25000 | T36: 10000 | U36: 翻訳費10,000円 | V36: =S36+T36 -> 35000 | W36: メール調査+同一機関のWeb面談で統合質問 | Z36: FALSE
A37: 36 | B37: 1. 木材の長期間利用による炭素貯蔵効果の評価手法の検討 | C37: (1) フランスのダイナミックLCAを含む海外での制度事例や検討内容の収集・分析 | D37: ① フランスRE2020におけるダイナミックLCA関連情報の収集・分析 | E37: (4) 関係機関及び専門家調査 | F37: ① | G37: 建築及びLCA関係者へのヒアリング | H37: ウ | I37: 制度運用上の留意点【サブ:メール調査】 | J37: 電子メール・Web面談ヒアリング | K37: 4 | L37: 1 | M37: 50 | N37: AIで質問票作成・回答要約、人間が検証 | O37: =ROUND(L37*(1-M37/100)*2,0)/2 -> 0.5 | P37: 2026年8月中旬 | Q37: 2026年10月中旬 | R37: 50000 | S37: =O37*R37 -> 25000 | T37: 10000 | U37: 翻訳費10,000円 | V37: =S37+T37 -> 35000 | W37: メール調査+同一機関のWeb面談で統合質問 | Z37: FALSE
A38: 37 | B38: 1. 木材の長期間利用による炭素貯蔵効果の評価手法の検討 | C38: (1) フランスのダイナミックLCAを含む海外での制度事例や検討内容の収集・分析 | D38: ① フランスRE2020におけるダイナミックLCA関連情報の収集・分析 | E38: (4) 関係機関及び専門家調査 | F38: ② | G38: EPDプログラム運営機関へのヒアリング | H38: ア | I38: EPD（建材及び建築物）のダイナミックLCA対応状況【メイン:Web面談】 | J38: 電子メール・Web面談ヒアリング | K38: 5 | L38: 3 | M38: 30 | N38: AIは質問票作成・議事録整理・要約のみ。実施は人間 | O38: =ROUND(L38*(1-M38/100)*2,0)/2 -> 2 | P38: 2026年8月中旬 | Q38: 2026年10月中旬 | R38: 50000 | S38: =O38*R38 -> 100000 | T38: 30000 | U38: 通訳費20,000円+謝礼10,000円 | V38: =S38+T38 -> 130000 | W38: ★メイン機関(EPD運営機関)1機関に集約。Web面談で実施 / Web面談1セッション約60-90分 | Z38: FALSE
A39: 38 | B39: 1. 木材の長期間利用による炭素貯蔵効果の評価手法の検討 | C39: (1) フランスのダイナミックLCAを含む海外での制度事例や検討内容の収集・分析 | D39: ① フランスRE2020におけるダイナミックLCA関連情報の収集・分析 | E39: (4) 関係機関及び専門家調査 | F39: ② | G39: EPDプログラム運営機関へのヒアリング | H39: イ | I39: エンドオブライフに係るシナリオの整備状況【サブ:メール調査】 | J39: 電子メール・Web面談ヒアリング | K39: 4 | L39: 1 | M39: 50 | N39: AIで質問票作成・回答要約、人間が検証 | O39: =ROUND(L39*(1-M39/100)*2,0)/2 -> 0.5 | P39: 2026年8月中旬 | Q39: 2026年10月中旬 | R39: 50000 | S39: =O39*R39 -> 25000 | T39: 10000 | U39: 翻訳費10,000円 | V39: =S39+T39 -> 35000 | W39: 同一機関のWeb面談で統合質問 / Web面談1セッション約60-90分 | Z39: FALSE
A40: 39 | B40: 1. 木材の長期間利用による炭素貯蔵効果の評価手法の検討 | C40: (1) フランスのダイナミックLCAを含む海外での制度事例や検討内容の収集・分析 | D40: ① フランスRE2020におけるダイナミックLCA関連情報の収集・分析 | E40: (4) 関係機関及び専門家調査 | F40: ② | G40: EPDプログラム運営機関へのヒアリング | H40: ウ | I40: 実務上の課題【サブ:メール調査】 | J40: 電子メール・Web面談ヒアリング | K40: 4 | L40: 1 | M40: 50 | N40: AIで質問票作成・回答要約、人間が検証 | O40: =ROUND(L40*(1-M40/100)*2,0)/2 -> 0.5 | P40: 2026年8月中旬 | Q40: 2026年10月中旬 | R40: 50000 | S40: =O40*R40 -> 25000 | T40: 10000 | U40: 翻訳費10,000円 | V40: =S40+T40 -> 35000 | W40: 同一機関のWeb面談で統合質問 / Web面談1セッション約60-90分 | Z40: FALSE
...

Sheet AI活用効果サマリー
A1: ブロック別 AI活用効果と費用サマリー
A3: 調査ブロック | B3: 項目数 | C3: AI活用前 工数(人日) | D3: AI活用後 工数(人日) | E3: 削減工数 (人日) | F3: 削減率 (%) | G3: 人件費合計 (円) | H3: 実際にかかる費用合計 (円)
A4: (1) 政策及び制度調査 | B4: =COUNTIF('調査業務リスト'!E2:E46,"(1) 政策及び制度調査") -> 14 | C4: =SUMIF('調査業務リスト'!E2:E46,"(1) 政策及び制度調査",'調査業務リスト'!L2:L46) -> 41 | D4: =SUMIF('調査業務リスト'!E2:E46,"(1) 政策及び制度調査",'調査業務リスト'!O2:O46) -> 16.5 | E4: =C4-D4 -> 24.5 | F4: =IFERROR(E4/C4,0) -> 0.59756098 | G4: =SUMIF('調査業務リスト'!E2:E46,"(1) 政策及び制度調査",'調査業務リスト'!S2:S46) -> 660000 | H4: =SUMIF('調査業務リスト'!E2:E46,"(1) 政策及び制度調査",'調査業務リスト'!V2:V46) -> 660000
A5: (2) 技術及び手法の調査 | B5: =COUNTIF('調査業務リスト'!E2:E46,"(2) 技術及び手法の調査") -> 9 | C5: =SUMIF('調査業務リスト'!E2:E46,"(2) 技術及び手法の調査",'調査業務リスト'!L2:L46) -> 30 | D5: =SUMIF('調査業務リスト'!E2:E46,"(2) 技術及び手法の調査",'調査業務リスト'!O2:O46) -> 17.5 | E5: =C5-D5 -> 12.5 | F5: =IFERROR(E5/C5,0) -> 0.41666667 | G5: =SUMIF('調査業務リスト'!E2:E46,"(2) 技術及び手法の調査",'調査業務リスト'!S2:S46) -> 700000 | H5: =SUMIF('調査業務リスト'!E2:E46,"(2) 技術及び手法の調査",'調査業務リスト'!V2:V46) -> 700000
A6: (3) 制度を支える情報基盤の構造把握 | B6: =COUNTIF('調査業務リスト'!E2:E46,"(3) 制度を支える情報基盤の構造把握") -> 10 | C6: =SUMIF('調査業務リスト'!E2:E46,"(3) 制度を支える情報基盤の構造把握",'調査業務リスト'!L2:L46) -> 32 | D6: =SUMIF('調査業務リスト'!E2:E46,"(3) 制度を支える情報基盤の構造把握",'調査業務リスト'!O2:O46) -> 13.5 | E6: =C6-D6 -> 18.5 | F6: =IFERROR(E6/C6,0) -> 0.578125 | G6: =SUMIF('調査業務リスト'!E2:E46,"(3) 制度を支える情報基盤の構造把握",'調査業務リスト'!S2:S46) -> 540000 | H6: =SUMIF('調査業務リスト'!E2:E46,"(3) 制度を支える情報基盤の構造把握",'調査業務リスト'!V2:V46) -> 540000
A7: (4) 関係機関及び専門家調査 | B7: =COUNTIF('調査業務リスト'!E2:E46,"(4) 関係機関及び専門家調査") -> 11 | C7: =SUMIF('調査業務リスト'!E2:E46,"(4) 関係機関及び専門家調査",'調査業務リスト'!L2:L46) -> 18 | D7: =SUMIF('調査業務リスト'!E2:E46,"(4) 関係機関及び専門家調査",'調査業務リスト'!O2:O46) -> 11 | E7: =C7-D7 -> 7 | F7: =IFERROR(E7/C7,0) -> 0.38888889 | G7: =SUMIF('調査業務リスト'!E2:E46,"(4) 関係機関及び専門家調査",'調査業務リスト'!S2:S46) -> 550000 | H7: =SUMIF('調査業務リスト'!E2:E46,"(4) 関係機関及び専門家調査",'調査業務リスト'!V2:V46) -> 720000
A8: 横断業務 (統合・PMO) | B8: =COUNTIF('調査業務リスト'!E2:E46,"横断業務 (統合・PMO)") -> 1 | C8: =SUMIF('調査業務リスト'!E2:E46,"横断業務 (統合・PMO)",'調査業務リスト'!L2:L46) -> 8 | D8: =SUMIF('調査業務リスト'!E2:E46,"横断業務 (統合・PMO)",'調査業務リスト'!O2:O46) -> 3 | E8: =C8-D8 -> 5 | F8: =IFERROR(E8/C8,0) -> 0.625 | G8: =SUMIF('調査業務リスト'!E2:E46,"横断業務 (統合・PMO)",'調査業務リスト'!S2:S46) -> 150000 | H8: =SUMIF('調査業務リスト'!E2:E46,"横断業務 (統合・PMO)",'調査業務リスト'!V2:V46) -> 150000
A9: AI利用ツール費用 | B9: 1 | C9: 0 | D9: 0 | E9: 0 | F9: 0 | G9: 0 | H9: 45000
A10: 合計 | B10: =SUM(B4:B9) -> 46 | C10: =SUM(C4:C9) -> 129 | D10: =SUM(D4:D9) -> 61.5 | E10: =SUM(E4:E9) -> 67.5 | F10: =IFERROR(E10/C10,0) -> 0.52325581 | G10: =SUM(G4:G9) -> 2600000 | H10: =SUM(H4:H9) -> 2815000
A12: 予算上限 | H12: 3000000
A13: 差額 (予算 − 見積) | H13: =H12-H10 -> 185000
A14: 予算消化率 | H14: =H10/H12 -> 0.93833333
A16: 【稼働量チェック】月別稼働量を反映
A17: 5月〜6月 (9週 × 週1.5日) | D17: 13.5 | E17: 人日
A18: 7月〜8月 (9週 × 週2.25日 ★授業減で増加) | D18: 20.25 | E18: 人日
A19: 9月〜10月中旬 (6週 × 週1.5日) | D19: 9 | E19: 人日
A20: 稼働可能総工数 | D20: =D17+D18+D19 -> 42.75 | E20: 人日
A21: 必要工数 (AI活用後) | D21: =D10 -> 61.5 | E21: 人日
A22: 稼働の余裕 | D22: =D20-D21 -> -18.75 | E22: 人日
A23: 【AI活用提案サマリー】
A24: ■ 高削減群 (削減率60%): フランス語文献の翻訳・要約・論点抽出
A25: → Claude/ChatGPTで初稿生成 + DeepLで翻訳補助。人間は妥当性検証と修正のみ。
A26: → 対象: ブロック(1)制度化背景全般、INIESデータベース構造分析、結果表示方式等
A28: ■ 中削減群 (削減率40-50%): 概念整理・比較表・データ構造分析
A29: → AIで比較表・概念図の初稿、人間が専門的精査。
A30: → 対象: 静的vs動的LCA比較、A-Dモジュール構造、評価指標整理等
A32: ■ 低削減群 (削減率20-30%): 専門解釈・計算根拠の精査
A33: → AIは資料整理・論点抽出のみ。最終解釈は人間。
A34: → 対象: 遅延排出評価根拠、貯蔵量算定方法、放射強制力等
A36: ■ 極低削減群 (削減率10-25%): ヒアリング実施
A37: → AIは質問票作成・議事録要約・後処理のみ。実施は人間。
... A44: ・AI出力をそのまま納品物に流用せず、必ず編集・統合する

Sheet スケジュール
A1: 実施スケジュール (2026年5月〜10月中旬)
A3: フェーズ | B3: 期間 | C3: 主な作業 | D3: 工数(人日)
A4: Phase 1: 制度化背景・基礎ガイダンス | B4: 2026年5月上旬 〜 6月初旬 (約5週) | C4: ブロック(1)①ア・イ・ウ + ④全般 (RE2020全体構造、制度導入背景、フランス林業戦略との関係性)。AI翻訳・要約フル活用で初期立ち上げ。 | D4: 約7-8人日
A5: Phase 2: 制度要件・技術手法調査 | B5: 2026年6月中旬 〜 8月上旬 (約7週) | C5: ブロック(1)残り + ブロック(2)技術・手法調査。動的LCA理論、評価指標、算定方法の整理。 | D5: 約10-11人日
A6: Phase 3: 情報基盤調査 + ヒアリング準備 | B6: 2026年7月上旬 〜 8月下旬 (並行) | C6: ブロック(3)INIES等のデータベース分析、炭素フローモデル仕様。並行してブロック(4)ヒアリング相手選定・打診・質問票作成。 | D6: 約7-8人日
A7: Phase 4: ヒアリング実施 + 取りまとめ | B7: 2026年8月中旬 〜 10月中旬 (約9週) | C7: ブロック(4)Web面談3機関(各1セッション)に集約 + サブ項目はメール調査。並行してパワポ形式の報告書作成(AI初稿+人間編集)、最終納品物作成。 | D7: 約7-8人日
A10: 【スケジュールの前提】
A11: ・月別稼働量: 5-6月=週1.5日(9週)、7-8月=週2.25日(9週・授業減で増加)、9-10月中旬=週1.5日(6週)
A12: ・稼働可能総工数: 13.5 + 20.25 + 9.0 = 42.75人日
A13: ・★優先群「制度化背景・基礎ガイダンス」は2026年5月上旬着手→6月初旬完了で他項目の基盤を整える
A14: ・残り項目は6月中旬から並行進行。技術・情報基盤調査は稼働増の7-8月に重点配分。
A15: ・ヒアリング系は8月中旬から開始(夏季休暇後)、3機関集約+メール調査で効率化
A16: ・AI活用前提のため、文献調査・概念整理・データ整理を早期に効率化
A17: ・最終納品形式: パワポ(ppt)スライドデック + 関連データ整理表
A18: ・最終納品: 2026年10月中旬目処

Sheet 最重要項目のみスコープ
A1: 【縮小スコープ案】重要度5項目のみに絞った場合の見積もり
A2: 稼働制約(週1.5日×24週=36人日)・予算300万円に確実に収めるため、重要度5(最重要)項目のみに絞った場合の試算
A4: No. | B4: 調査ブロック | C4: 大細目 | D4: 細目記号 | E4: 細目内容 | F4: 重要度 | G4: AI活用前 工数(人日) | H4: AI削減率(%) | I4: AI活用ツール・手法 | J4: AI活用後 工数(人日) | K4: 人件費単価 (円/人日) | L4: 人件費(円) | M4: その他コスト (円) | N4: 実際にかかる費用 (円) | O4: 備考
A5: 1 | B5: (1) 政策及び制度調査 | C5: 建築環境性能評価制度の全体構造 | D5: ア | E5: RE2020における建築物LCAの位置付け | F5: 5 | G5: 3 | H5: 60 | I5: Claude/ChatGPTでフランス語文献の翻訳・要約・論点抽出を一次処理、DeepLで補助翻訳、人間が検証 | J5: =ROUND(G5*(1-H5/100)*2,0)/2 -> 1 | K5: 40000 | L5: =J5*K5 -> 40000 | M5: 0 | N5: =L5+M5 -> 40000 | O5: ★優先群(5月-6月初旬)
A6: 2 | B6: (1) 政策及び制度調査 | C6: 建築環境性能評価制度の全体構造 | D6: イ | E6: 環境性能評価方法（非住宅・住宅、新築・既築住宅等） | F6: 5 | G6: 4 | H6: 60 | I6: Claude/ChatGPTでフランス語文献の翻訳・要約・論点抽出を一次処理、DeepLで補助翻訳、人間が検証 | J6: =ROUND(G6*(1-H6/100)*2,0)/2 -> 1.5 | K6: 40000 | L6: =J6*K6 -> 60000 | M6: 0 | N6: =L6+M6 -> 60000 | O6: ★優先群(5月-6月初旬)
A7: 3 | B7: (1) 政策及び制度調査 | C7: ダイナミックLCAの要件整理 | D7: ア | E7: 対象建築物の種別と範囲、並びに導入時の段階適用内容 | F7: 5 | G7: 3 | H7: 65 | I7: AIで文献翻訳・要件抽出を自動化 | J7: =ROUND(G7*(1-H7/100)*2,0)/2 -> 1 | K7: 40000 | L7: =J7*K7 -> 40000 | M7: 0 | N7: =L7+M7 -> 40000
A8: 4 | B8: (1) 政策及び制度調査 | C8: ダイナミックLCAの要件整理 | D8: イ | E8: 遅延排出の評価根拠 | F8: 5 | G8: 4 | H8: 50 | I8: AIで根拠資料の翻訳・要約、人間が解釈精査 | J8: =ROUND(G8*(1-H8/100)*2,0)/2 -> 2 | K8: 40000 | L8: =J8*K8 -> 80000 | M8: 0 | N8: =L8+M8 -> 80000 | O8: 解釈判断が重要
A9: 5 | B9: (1) 政策及び制度調査 | C9: 生物由来炭素及び炭素貯蔵評価の制度的位置付け | D9: ア | E9: 貯蔵量算定方法 | F9: 5 | G9: 4 | H9: 50 | I9: AIで算定式・計算例の翻訳整理、人間が精査 | J9: =ROUND(G9*(1-H9/100)*2,0)/2 -> 2 | K9: 40000 | L9: =J9*K9 -> 80000 | M9: 0 | N9: =L9+M9 -> 80000 | O9: 計算根拠の精査が必要
A10: 6 | B10: (1) 政策及び制度調査 | C10: 生物由来炭素及び炭素貯蔵評価の制度的位置付け | D10: イ | E10: 評価期間の設定根拠 | F10: 5 | G10: 3 | H10: 65 | I10: AIで根拠資料の翻訳・要点抽出 | J10: =ROUND(G10*(1-H10/100)*2,0)/2 -> 1 | K10: 40000 | L10: =J10*K10 -> 40000 | M10: 0 | N10: =L10+M10 -> 40000
A11: 7 | B11: (2) 技術及び手法の調査 | C11: ダイナミックLCAの理論的枠組み | D11: ア | E11: 動的LCA（時間軸評価）導入の基本概念 | F11: 5 | G11: 3 | H11: 40 | I11: AIで概念整理・比較表の初稿生成、人間が専門的精査・修正 | J11: =ROUND(G11*(1-H11/100)*2,0)/2 -> 2 | K11: 40000 | L11: =J11*K11 -> 80000 | M11: 0 | N11: =L11+M11 -> 80000 | O11: 理論部分は人間の理解が必須
A12: 8 | B12: (2) 技術及び手法の調査 | C12: ダイナミックLCAの理論的枠組み | D12: イ | E12: 評価期間の根拠 | F12: 5 | G12: 3 | H12: 40 | I12: AIで概念整理・比較表の初稿生成、人間が専門的精査・修正 | J12: =ROUND(G12*(1-H12/100)*2,0)/2 -> 2 | K12: 40000 | L12: =J12*K12 -> 80000 | M12: 0 | N12: =L12+M12 -> 80000
A13: 9 | B13: (2) 技術及び手法の調査 | C13: ダイナミックLCAの理論的枠組み | D13: ウ | E13: 従来型静的LCA（GWP100）との差異 | F13: 5 | G13: 4 | H13: 50 | I13: AIで概念整理・比較表の初稿生成、人間が専門的精査・修正 | J13: =ROUND(G13*(1-H13/100)*2,0)/2 -> 2 | K13: 40000 | L13: =J13*K13 -> 80000 | M13: 0 | N13: =L13+M13 -> 80000 | O13: 比較表をAIで初稿生成
A14: 10 | B14: (2) 技術及び手法の調査 | C14: 評価指標及び算定方法 | D14: ア | E14: 時間軸評価の処理方法、パラメータ根拠 | F14: 5 | G14: 4 | H14: 30 | I14: AIで概念整理・比較表の初稿生成、人間が専門的精査・修正 | J14: =ROUND(G14*(1-H14/100)*2,0)/2 -> 3 | K14: 40000 | L14: =J14*K14 -> 120000 | M14: 0 | N14: =L14+M14 -> 120000 | O14: 数式・パラメータの精査が必要
A15: 11 | B15: (2) 技術及び手法の調査 | C15: 評価指標及び算定方法 | D15: イ | E15: 炭素循環（吸収・固定・放出）の扱い | F15: 5 | G15: 4 | H15: 40 | I15: AIで概念整理・比較表の初稿生成、人間が専門的精査・修正 | J15: =ROUND(G15*(1-H15/100)*2,0)/2 -> 2.5 | K15: 40000 | L15: =J15*K15 -> 100000 | M15: 0 | N15: =L15+M15 -> 100000
A16: 12 | B16: (3) 制度を支える情報基盤の構造把握 | C16: 建材のCO₂等排出量原単位データベースの構造分析 | D16: ア | E16: INIESにおけるデータ格納状況 | F16: 5 | G16: 4 | H16: 70 | I16: AIでDBスキーマ・データ構造を自動分析 | J16: =ROUND(G16*(1-H16/100)*2,0)/2 -> 1 | K16: 40000 | L16: =J16*K16 -> 40000 | M16: 0 | N16: =L16+M16 -> 40000 | O16: DBスキーマ分析はAIが特に得意
A17: 13 | B17: (3) 制度を支える情報基盤の構造把握 | C17: 建材のCO₂等排出量原単位データベースの構造分析 | D17: イ | E17: 動的評価に必要なパラメータの設定状況 | F17: 5 | G17: 4 | H17: 65 | I17: AIでパラメータ仕様の翻訳・整理を自動化 | J17: =ROUND(G17*(1-H17/100)*2,0)/2 -> 1.5 | K17: 40000 | L17: =J17*K17 -> 60000 | M17: 0 | N17: =L17+M17 -> 60000
A18: 14 | B18: (3) 制度を支える情報基盤の構造把握 | C18: 炭素フローモデルの仕様把握 | D18: ア | E18: 木材製品等の炭素貯蔵機能の評価方法 | F18: 5 | G18: 4 | H18: 40 | I18: AIで概念整理・比較表の初稿生成、人間が専門的精査・修正 | J18: =ROUND(G18*(1-H18/100)*2,0)/2 -> 2.5 | K18: 40000 | L18: =J18*K18 -> 100000 | M18: 0 | N18: =L18+M18 -> 100000 | O18: 専門的解釈が必要
A19: 15 | B19: (3) 制度を支える情報基盤の構造把握 | C19: 炭素フローモデルの仕様把握 | D19: イ | E19: エンドオブライフシナリオのモデル化方法 | F19: 5 | G19: 4 | H19: 50 | I19: AIでシナリオ定義の翻訳・整理 | J19: =ROUND(G19*(1-H19/100)*2,0)/2 -> 2 | K19: 40000 | L19: =J19*K19 -> 80000 | M19: 0 | N19: =L19+M19 -> 80000
A20: 16 | B20: (4) 関係機関及び専門家調査 | C20: 建築及びLCA関係者へのヒアリング | D20: ア | E20: ダイナミックLCA導入のメリット・デメリット【メイン:Web面談】 | F20: 5 | G20: 4 | H20: 30 | I20: AIは質問票作成・議事録整理・要約のみ。実施は人間 | J20: =ROUND(G20*(1-H20/100)*2,0)/2 -> 3 | K20: 50000 | L20: =J20*K20 -> 150000 | M20: 30000 | N20: =L20+M20 -> 180000 | O20: メイン1機関 Web面談 / 通訳費20,000円+謝礼10,000円
A21: 17 | B21: (4) 関係機関及び専門家調査 | C21: EPDプログラム運営機関へのヒアリング | D21: ア | E21: EPD（建材及び建築物）のダイナミックLCA対応状況【メイン:Web面談】 | F21: 5 | G21: 3 | H21: 30 | I21: AIは質問票作成・議事録整理・要約のみ。実施は人間 | J21: =ROUND(G21*(1-H21/100)*2,0)/2 -> 2 | K21: 50000 | L21: =J21*K21 -> 100000 | M21: 30000 | N21: =L21+M21 -> 130000 | O21: メイン1機関 Web面談 / 通訳費20,000円+謝礼10,000円
A22: OH | B22: 横断業務 (統合・PMO) | C22: プロジェクトマネジメント・全体統合・パワポ報告書作成 | D22: ― | E22: キックオフ、定例MTG、進捗管理、パワポ報告書作成・納品 | F22: 5 | G22: 5 | H22: 60 | I22: AIでパワポ初稿生成、人間が編集確認 | J22: =ROUND(G22*(1-H22/100)*2,0)/2 -> 2 | K22: 50000 | L22: =J22*K22 -> 100000 | M22: 0 | N22: =L22+M22 -> 100000 | O22: スコープ縮小に伴い圧縮。パワポ形式の納品物
A23: AI | B23: AI利用ツール費用 | E23: Claude Pro/ChatGPT Plus/DeepL Pro等 6ヶ月分 | L23: 0 | M23: 45000 | N23: =L23+M23 -> 45000 | O23: AI/翻訳ツールサブスク 6ヶ月分
B24: 合計 | G24: =SUM(G5:G22) -> 67 | J24: =SUM(J5:J22) -> 34 | L24: =SUM(L5:L23) -> 1430000 | M24: =SUM(M5:M23) -> 105000 | N24: =SUM(N5:N23) -> 1535000
B26: 【予算チェック】
B27: 予算上限 | N27: 3000000
B28: 差額（予算 − 見積） | N28: =N27-N24 -> 1465000
B29: 予算消化率 | N29: =N24/N27 -> 0.51166667
B31: 【稼働量チェック】月別稼働量を反映
B32: 5月〜6月 (9週 × 週1.5日) | J32: 13.5 | K32: 人日
B33: 7月〜8月 (9週 × 週2.25日 ★授業減で増加) | J33: 20.25 | K33: 人日
B34: 9月〜10月中旬 (6週 × 週1.5日) | J34: 9 | K34: 人日
B35: 稼働可能総工数 | J35: =J32+J33+J34 -> 42.75 | K35: 人日
B36: 必要工数 (AI活用後) | J36: =J24 -> 34 | K36: 人日
B37: 稼働の余裕 | J37: =J35-J36 -> 8.75 | K37: 人日
B40: 【スコープ縮小の考え方】
B41: ■ 採用基準: 制度の根幹に関わる「重要度5」項目のみを対象 (全44項目→17項目)
B42: ■ ブロック(1) 政策・制度調査: 14項目中 6項目を採用
B43: → RE2020 LCA位置付け、評価方法、要件整理、貯蔵量算定、評価期間根拠など制度理解の核に絞る
B44: → 重要度4以下の制度導入背景・国家戦略・Level(s)・サーキュラーエコノミー等は除外
B46: ■ ブロック(2) 技術・手法調査: 9項目中 5項目を採用
...
